Workbook

Sheet Calculadora
A1: Calculadora de costo mensual — conectores Kafka → Confluent Cloud | AA1: =IF($B$7="Basic",0.05,IF($B$7="Standard",0.035,IF($B$7="Enterprise",0.02,IF($B$7="Dedicated",0.014,0.05)))) -> 0.014
A2: Amarillo = eliges o escribes. Verde = se calcula solo. Significado de cada opción: hoja «Guía de opciones» (o el comentario al pasar el cursor por el nombre). 1) Ajusta las opciones. 2) Elige el conector y rellena tareas y GB/mes. | AA2: =IF(OR($B$9="Sí",$B$9="Si"),0.27778*$B$5,0) -> 0
A4: 1. Opciones — pasa el cursor por el nombre del campo o abre la hoja «Guía de opciones»
A5: Horas / mes | B5: 730 | C5: Horas del mes que el conector está activo. 730 = mes promedio. No lo cambies si corre 24×7.
A6: Tarifa de tarea | B6: Media | C6: Precio por cada unidad de trabajo del conector, cada hora. Min = bajo; Media = típico; Max = conservador.
A7: Tipo de cluster Kafka | B7: Dedicated | C7: Plan del cluster donde aterrizan los datos. Cambia el precio por GB escrito, no el del conector.
A8: Incluir escritura a Kafka | B8: Sí | C8: ¿El conector mete datos en Confluent Cloud? Sí = se suma el peaje por GB de entrada. Source = Sí; Sink = No.
A9: Connect dedicado | B9: No | C9: Cargo fijo extra de Connect si el cluster Kafka es Dedicated. Un cargo del entorno, no por cada conector.
A10: PrivateLink | B10: Sí | C10: Red privada banco–nube (sin internet público). Sí solo si Arquitectura lo exige.
A11: Custom SMT | B11: No | C11: Transformaciones de datos a medida. No = las estándar. Sí = recargo.
A13: COSTO MENSUAL (USD)
A14: Tareas + datos Connect | C14: =SUM(K21:K32)+SUM(L21:L32) -> 1260.1115
A15: PrivateLink + SMT + Connect dedicado | C15: =SUM(M21:N32)+AA2 -> 109.5
A16: Escritura a Kafka (ingress, solo Source) | C16: =SUM(O21:O32) -> 210
A17: TOTAL ESTIMADO / MES | C17: =C14+C15+C16 -> 1579.6115
A19: 2. Conectores — elige en la flecha de la columna A, escribe tareas y GB/mes. Puedes añadir varias filas. Deja vacías las que no uses.
A20: Conector (elige ▼) | B20: Tareas (tasks.max) | C20: GB / mes | D20: Override $/tarea·h (opcional) | E20: Tipo | F20: Connect $/mes | G20: TOTAL $/mes | H20: Nota
A21: Azure Event Hubs [Source] | B21: 3 | C21: 15000 | E21: =IF(A21="","",IFERROR(INDEX('Tarifas oficiales'!$B$4:$B$101,MATCH(A21,'Tarifas oficiales'!$C$4:$C$101,0)),"")) -> Source | F21: =K21+L21+M21+N21 -> 497.3115 | G21: =F21+O21 -> 707.3115 | H21: =IF(A21="","",IF(NOT(ISNUMBER(I21)),"⚠ Contact us: pon el $/tarea·h en Override (columna D)",IF(E21="Sink","Sink: sale del cluster. Ingress = 0.","Source: escribe a Confluent Cloud."))) -> Source: escribe a Confluent Cloud. | I21: =IF(A21="","",IF(D21<>"",D21,IFERROR(IF($B$6="Min",INDEX('Tarifas oficiales'!$D$4:$D$101,MATCH(A21,'Tarifas oficiales'!$C$4:$C$101,0)),IF($B$6="Max",INDEX('Tarifas oficiales'!$E$4:$E$101,MATCH(A21,'Tarifas oficiales'!$C$4:$C$101,0)),INDEX('Tarifas oficiales'!$F$4:$F$101,MATCH(A21,'Tarifas oficiales'!$C$4:$C$101,0)))),""))) -> 0.02585 | J21: =IF(A21="","",IFERROR(INDEX('Tarifas oficiales'!$G$4:$G$101,MATCH(A21,'Tarifas oficiales'!$C$4:$C$101,0)),0.025)) -> 0.025 | K21: =IF(OR(A21="",B21="",NOT(ISNUMBER(I21))),0,B21*I21*$B$5) -> 56.6115 | L21: =IF(OR(A21="",C21="",NOT(ISNUMBER(J21))),0,C21*J21) -> 375 | M21: =IF(OR(A21="",B21=""),0,IF(OR($B$10="Sí",$B$10="Si"),B21*0.03*$B$5,0)) -> 65.7 | N21: =IF(OR(A21="",B21=""),0,IF(OR($B$11="Sí",$B$11="Si"),B21*0.05*$B$5,0)) -> 0 | O21: =IF(OR(A21="",C21="",NOT(OR($B$8="Sí",$B$8="Si"))),0,IF(ISNUMBER(SEARCH("Source",E21)),C21*$AA$1,0)) -> 210
A22: Azure Cosmos DB [Sink] | B22: 2 | C22: 20000 | E22: =IF(A22="","",IFERROR(INDEX('Tarifas oficiales'!$B$4:$B$101,MATCH(A22,'Tarifas oficiales'!$C$4:$C$101,0)),"")) -> Sink | F22: =K22+L22+M22+N22 -> 872.3 | G22: =F22+O22 -> 872.3 | H22: =IF(A22="","",IF(NOT(ISNUMBER(I22)),"⚠ Contact us: pon el $/tarea·h en Override (columna D)",IF(E22="Sink","Sink: sale del cluster. Ingress = 0.","Source: escribe a Confluent Cloud."))) -> Sink: sale del cluster. Ingress = 0. | I22: =IF(A22="","",IF(D22<>"",D22,IFERROR(IF($B$6="Min",INDEX('Tarifas oficiales'!$D$4:$D$101,MATCH(A22,'Tarifas oficiales'!$C$4:$C$101,0)),IF($B$6="Max",INDEX('Tarifas oficiales'!$E$4:$E$101,MATCH(A22,'Tarifas oficiales'!$C$4:$C$101,0)),INDEX('Tarifas oficiales'!$F$4:$F$101,MATCH(A22,'Tarifas oficiales'!$C$4:$C$101,0)))),""))) -> 0.225 | J22: =IF(A22="","",IFERROR(INDEX('Tarifas oficiales'!$G$4:$G$101,MATCH(A22,'Tarifas oficiales'!$C$4:$C$101,0)),0.025)) -> 0.025 | K22: =IF(OR(A22="",B22="",NOT(ISNUMBER(I22))),0,B22*I22*$B$5) -> 328.5 | L22: =IF(OR(A22="",C22="",NOT(ISNUMBER(J22))),0,C22*J22) -> 500 | M22: =IF(OR(A22="",B22=""),0,IF(OR($B$10="Sí",$B$10="Si"),B22*0.03*$B$5,0)) -> 43.8 | N22: =IF(OR(A22="",B22=""),0,IF(OR($B$11="Sí",$B$11="Si"),B22*0.05*$B$5,0)) -> 0 | O22: =IF(OR(A22="",C22="",NOT(OR($B$8="Sí",$B$8="Si"))),0,IF(ISNUMBER(SEARCH("Source",E22)),C22*$AA$1,0)) -> 0
E23: =IF(A23="","",IFERROR(INDEX('Tarifas oficiales'!$B$4:$B$101,MATCH(A23,'Tarifas oficiales'!$C$4:$C$101,0)),"")) | F23: =K23+L23+M23+N23 -> 0 | G23: =F23+O23 -> 0 | H23: =IF(A23="","",IF(NOT(ISNUMBER(I23)),"⚠ Contact us: pon el $/tarea·h en Override (columna D)",IF(E23="Sink","Sink: sale del cluster. Ingress = 0.","Source: escribe a Confluent Cloud."))) | I23: =IF(A23="","",IF(D23<>"",D23,IFERROR(IF($B$6="Min",INDEX('Tarifas oficiales'!$D$4:$D$101,MATCH(A23,'Tarifas oficiales'!$C$4:$C$101,0)),IF($B$6="Max",INDEX('Tarifas oficiales'!$E$4:$E$101,MATCH(A23,'Tarifas oficiales'!$C$4:$C$101,0)),INDEX('Tarifas oficiales'!$F$4:$F$101,MATCH(A23,'Tarifas oficiales'!$C$4:$C$101,0)))),""))) | J23: =IF(A23="","",IFERROR(INDEX('Tarifas oficiales'!$G$4:$G$101,MATCH(A23,'Tarifas oficiales'!$C$4:$C$101,0)),0.025)) | K23: =IF(OR(A23="",B23="",NOT(ISNUMBER(I23))),0,B23*I23*$B$5) -> 0 | L23: =IF(OR(A23="",C23="",NOT(ISNUMBER(J23))),0,C23*J23) -> 0 | M23: =IF(OR(A23="",B23=""),0,IF(OR($B$10="Sí",$B$10="Si"),B23*0.03*$B$5,0)) -> 0 | N23: =IF(OR(A23="",B23=""),0,IF(OR($B$11="Sí",$B$11="Si"),B23*0.05*$B$5,0)) -> 0 | O23: =IF(OR(A23="",C23="",NOT(OR($B$8="Sí",$B$8="Si"))),0,IF(ISNUMBER(SEARCH("Source",E23)),C23*$AA$1,0)) -> 0
E24: =IF(A24="","",IFERROR(INDEX('Tarifas oficiales'!$B$4:$B$101,MATCH(A24,'Tarifas oficiales'!$C$4:$C$101,0)),"")) | F24: =K24+L24+M24+N24 -> 0 | G24: =F24+O24 -> 0 | H24: =IF(A24="","",IF(NOT(ISNUMBER(I24)),"⚠ Contact us: pon el $/tarea·h en Override (columna D)",IF(E24="Sink","Sink: sale del cluster. Ingress = 0.","Source: escribe a Confluent Cloud."))) | I24: =IF(A24="","",IF(D24<>"",D24,IFERROR(IF($B$6="Min",INDEX('Tarifas oficiales'!$D$4:$D$101,MATCH(A24,'Tarifas oficiales'!$C$4:$C$101,0)),IF($B$6="Max",INDEX('Tarifas oficiales'!$E$4:$E$101,MATCH(A24,'Tarifas oficiales'!$C$4:$C$101,0)),INDEX('Tarifas oficiales'!$F$4:$F$101,MATCH(A24,'Tarifas oficiales'!$C$4:$C$101,0)))),""))) | J24: =IF(A24="","",IFERROR(INDEX('Tarifas oficiales'!$G$4:$G$101,MATCH(A24,'Tarifas oficiales'!$C$4:$C$101,0)),0.025)) | K24: =IF(OR(A24="",B24="",NOT(ISNUMBER(I24))),0,B24*I24*$B$5) -> 0 | L24: =IF(OR(A24="",C24="",NOT(ISNUMBER(J24))),0,C24*J24) -> 0 | M24: =IF(OR(A24="",B24=""),0,IF(OR($B$10="Sí",$B$10="Si"),B24*0.03*$B$5,0)) -> 0 | N24: =IF(OR(A24="",B24=""),0,IF(OR($B$11="Sí",$B$11="Si"),B24*0.05*$B$5,0)) -> 0 | O24: =IF(OR(A24="",C24="",NOT(OR($B$8="Sí",$B$8="Si"))),0,IF(ISNUMBER(SEARCH("Source",E24)),C24*$AA$1,0)) -> 0
E25: =IF(A25="","",IFERROR(INDEX('Tarifas oficiales'!$B$4:$B$101,MATCH(A25,'Tarifas oficiales'!$C$4:$C$101,0)),"")) | F25: =K25+L25+M25+N25 -> 0 | G25: =F25+O25 -> 0 | H25: =IF(A25="","",IF(NOT(ISNUMBER(I25)),"⚠ Contact us: pon el $/tarea·h en Override (columna D)",IF(E25="Sink","Sink: sale del cluster. Ingress = 0.","Source: escribe a Confluent Cloud."))) | I25: =IF(A25="","",IF(D25<>"",D25,IFERROR(IF($B$6="Min",INDEX('Tarifas oficiales'!$D$4:$D$101,MATCH(A25,'Tarifas oficiales'!$C$4:$C$101,0)),IF($B$6="Max",INDEX('Tarifas oficiales'!$E$4:$E$101,MATCH(A25,'Tarifas oficiales'!$C$4:$C$101,0)),INDEX('Tarifas oficiales'!$F$4:$F$101,MATCH(A25,'Tarifas oficiales'!$C$4:$C$101,0)))),""))) | J25: =IF(A25="","",IFERROR(INDEX('Tarifas oficiales'!$G$4:$G$101,MATCH(A25,'Tarifas oficiales'!$C$4:$C$101,0)),0.025)) | K25: =IF(OR(A25="",B25="",NOT(ISNUMBER(I25))),0,B25*I25*$B$5) -> 0 | L25: =IF(OR(A25="",C25="",NOT(ISNUMBER(J25))),0,C25*J25) -> 0 | M25: =IF(OR(A25="",B25=""),0,IF(OR($B$10="Sí",$B$10="Si"),B25*0.03*$B$5,0)) -> 0 | N25: =IF(OR(A25="",B25=""),0,IF(OR($B$11="Sí",$B$11="Si"),B25*0.05*$B$5,0)) -> 0 | O25: =IF(OR(A25="",C25="",NOT(OR($B$8="Sí",$B$8="Si"))),0,IF(ISNUMBER(SEARCH("Source",E25)),C25*$AA$1,0)) -> 0
E26: =IF(A26="","",IFERROR(INDEX('Tarifas oficiales'!$B$4:$B$101,MATCH(A26,'Tarifas oficiales'!$C$4:$C$101,0)),"")) | F26: =K26+L26+M26+N26 -> 0 | G26: =F26+O26 -> 0 | H26: =IF(A26="","",IF(NOT(ISNUMBER(I26)),"⚠ Contact us: pon el $/tarea·h en Override (columna D)",IF(E26="Sink","Sink: sale del cluster. Ingress = 0.","Source: escribe a Confluent Cloud."))) | I26: =IF(A26="","",IF(D26<>"",D26,IFERROR(IF($B$6="Min",INDEX('Tarifas oficiales'!$D$4:$D$101,MATCH(A26,'Tarifas oficiales'!$C$4:$C$101,0)),IF($B$6="Max",INDEX('Tarifas oficiales'!$E$4:$E$101,MATCH(A26,'Tarifas oficiales'!$C$4:$C$101,0)),INDEX('Tarifas oficiales'!$F$4:$F$101,MATCH(A26,'Tarifas oficiales'!$C$4:$C$101,0)))),""))) | J26: =IF(A26="","",IFERROR(INDEX('Tarifas oficiales'!$G$4:$G$101,MATCH(A26,'Tarifas oficiales'!$C$4:$C$101,0)),0.025)) | K26: =IF(OR(A26="",B26="",NOT(ISNUMBER(I26))),0,B26*I26*$B$5) -> 0 | L26: =IF(OR(A26="",C26="",NOT(ISNUMBER(J26))),0,C26*J26) -> 0 | M26: =IF(OR(A26="",B26=""),0,IF(OR($B$10="Sí",$B$10="Si"),B26*0.03*$B$5,0)) -> 0 | N26: =IF(OR(A26="",B26=""),0,IF(OR($B$11="Sí",$B$11="Si"),B26*0.05*$B$5,0)) -> 0 | O26: =IF(OR(A26="",C26="",NOT(OR($B$8="Sí",$B$8="Si"))),0,IF(ISNUMBER(SEARCH("Source",E26)),C26*$AA$1,0)) -> 0
E27: =IF(A27="","",IFERROR(INDEX('Tarifas oficiales'!$B$4:$B$101,MATCH(A27,'Tarifas oficiales'!$C$4:$C$101,0)),"")) | F27: =K27+L27+M27+N27 -> 0 | G27: =F27+O27 -> 0 | H27: =IF(A27="","",IF(NOT(ISNUMBER(I27)),"⚠ Contact us: pon el $/tarea·h en Override (columna D)",IF(E27="Sink","Sink: sale del cluster. Ingress = 0.","Source: escribe a Confluent Cloud."))) | I27: =IF(A27="","",IF(D27<>"",D27,IFERROR(IF($B$6="Min",INDEX('Tarifas oficiales'!$D$4:$D$101,MATCH(A27,'Tarifas oficiales'!$C$4:$C$101,0)),IF($B$6="Max",INDEX('Tarifas oficiales'!$E$4:$E$101,MATCH(A27,'Tarifas oficiales'!$C$4:$C$101,0)),INDEX('Tarifas oficiales'!$F$4:$F$101,MATCH(A27,'Tarifas oficiales'!$C$4:$C$101,0)))),""))) | J27: =IF(A27="","",IFERROR(INDEX('Tarifas oficiales'!$G$4:$G$101,MATCH(A27,'Tarifas oficiales'!$C$4:$C$101,0)),0.025)) | K27: =IF(OR(A27="",B27="",NOT(ISNUMBER(I27))),0,B27*I27*$B$5) -> 0 | L27: =IF(OR(A27="",C27="",NOT(ISNUMBER(J27))),0,C27*J27) -> 0 | M27: =IF(OR(A27="",B27=""),0,IF(OR($B$10="Sí",$B$10="Si"),B27*0.03*$B$5,0)) -> 0 | N27: =IF(OR(A27="",B27=""),0,IF(OR($B$11="Sí",$B$11="Si"),B27*0.05*$B$5,0)) -> 0 | O27: =IF(OR(A27="",C27="",NOT(OR($B$8="Sí",$B$8="Si"))),0,IF(ISNUMBER(SEARCH("Source",E27)),C27*$AA$1,0)) -> 0
E28: =IF(A28="","",IFERROR(INDEX('Tarifas oficiales'!$B$4:$B$101,MATCH(A28,'Tarifas oficiales'!$C$4:$C$101,0)),"")) | F28: =K28+L28+M28+N28 -> 0 | G28: =F28+O28 -> 0 | H28: =IF(A28="","",IF(NOT(ISNUMBER(I28)),"⚠ Contact us: pon el $/tarea·h en Override (columna D)",IF(E28="Sink","Sink: sale del cluster. Ingress = 0.","Source: escribe a Confluent Cloud."))) | I28: =IF(A28="","",IF(D28<>"",D28,IFERROR(IF($B$6="Min",INDEX('Tarifas oficiales'!$D$4:$D$101,MATCH(A28,'Tarifas oficiales'!$C$4:$C$101,0)),IF($B$6="Max",INDEX('Tarifas oficiales'!$E$4:$E$101,MATCH(A28,'Tarifas oficiales'!$C$4:$C$101,0)),INDEX('Tarifas oficiales'!$F$4:$F$101,MATCH(A28,'Tarifas oficiales'!$C$4:$C$101,0)))),""))) | J28: =IF(A28="","",IFERROR(INDEX('Tarifas oficiales'!$G$4:$G$101,MATCH(A28,'Tarifas oficiales'!$C$4:$C$101,0)),0.025)) | K28: =IF(OR(A28="",B28="",NOT(ISNUMBER(I28))),0,B28*I28*$B$5) -> 0 | L28: =IF(OR(A28="",C28="",NOT(ISNUMBER(J28))),0,C28*J28) -> 0 | M28: =IF(OR(A28="",B28=""),0,IF(OR($B$10="Sí",$B$10="Si"),B28*0.03*$B$5,0)) -> 0 | N28: =IF(OR(A28="",B28=""),0,IF(OR($B$11="Sí",$B$11="Si"),B28*0.05*$B$5,0)) -> 0 | O28: =IF(OR(A28="",C28="",NOT(OR($B$8="Sí",$B$8="Si"))),0,IF(ISNUMBER(SEARCH("Source",E28)),C28*$AA$1,0)) -> 0
E29: =IF(A29="","",IFERROR(INDEX('Tarifas oficiales'!$B$4:$B$101,MATCH(A29,'Tarifas oficiales'!$C$4:$C$101,0)),"")) | F29: =K29+L29+M29+N29 -> 0 | G29: =F29+O29 -> 0 | H29: =IF(A29="","",IF(NOT(ISNUMBER(I29)),"⚠ Contact us: pon el $/tarea·h en Override (columna D)",IF(E29="Sink","Sink: sale del cluster. Ingress = 0.","Source: escribe a Confluent Cloud."))) | I29: =IF(A29="","",IF(D29<>"",D29,IFERROR(IF($B$6="Min",INDEX('Tarifas oficiales'!$D$4:$D$101,MATCH(A29,'Tarifas oficiales'!$C$4:$C$101,0)),IF($B$6="Max",INDEX('Tarifas oficiales'!$E$4:$E$101,MATCH(A29,'Tarifas oficiales'!$C$4:$C$101,0)),INDEX('Tarifas oficiales'!$F$4:$F$101,MATCH(A29,'Tarifas oficiales'!$C$4:$C$101,0)))),""))) | J29: =IF(A29="","",IFERROR(INDEX('Tarifas oficiales'!$G$4:$G$101,MATCH(A29,'Tarifas oficiales'!$C$4:$C$101,0)),0.025)) | K29: =IF(OR(A29="",B29="",NOT(ISNUMBER(I29))),0,B29*I29*$B$5) -> 0 | L29: =IF(OR(A29="",C29="",NOT(ISNUMBER(J29))),0,C29*J29) -> 0 | M29: =IF(OR(A29="",B29=""),0,IF(OR($B$10="Sí",$B$10="Si"),B29*0.03*$B$5,0)) -> 0 | N29: =IF(OR(A29="",B29=""),0,IF(OR($B$11="Sí",$B$11="Si"),B29*0.05*$B$5,0)) -> 0 | O29: =IF(OR(A29="",C29="",NOT(OR($B$8="Sí",$B$8="Si"))),0,IF(ISNUMBER(SEARCH("Source",E29)),C29*$AA$1,0)) -> 0
E30: =IF(A30="","",IFERROR(INDEX('Tarifas oficiales'!$B$4:$B$101,MATCH(A30,'Tarifas oficiales'!$C$4:$C$101,0)),"")) | F30: =K30+L30+M30+N30 -> 0 | G30: =F30+O30 -> 0 | H30: =IF(A30="","",IF(NOT(ISNUMBER(I30)),"⚠ Contact us: pon el $/tarea·h en Override (columna D)",IF(E30="Sink","Sink: sale del cluster. Ingress = 0.","Source: escribe a Confluent Cloud."))) | I30: =IF(A30="","",IF(D30<>"",D30,IFERROR(IF($B$6="Min",INDEX('Tarifas oficiales'!$D$4:$D$101,MATCH(A30,'Tarifas oficiales'!$C$4:$C$101,0)),IF($B$6="Max",INDEX('Tarifas oficiales'!$E$4:$E$101,MATCH(A30,'Tarifas oficiales'!$C$4:$C$101,0)),INDEX('Tarifas oficiales'!$F$4:$F$101,MATCH(A30,'Tarifas oficiales'!$C$4:$C$101,0)))),""))) | J30: =IF(A30="","",IFERROR(INDEX('Tarifas oficiales'!$G$4:$G$101,MATCH(A30,'Tarifas oficiales'!$C$4:$C$101,0)),0.025)) | K30: =IF(OR(A30="",B30="",NOT(ISNUMBER(I30))),0,B30*I30*$B$5) -> 0 | L30: =IF(OR(A30="",C30="",NOT(ISNUMBER(J30))),0,C30*J30) -> 0 | M30: =IF(OR(A30="",B30=""),0,IF(OR($B$10="Sí",$B$10="Si"),B30*0.03*$B$5,0)) -> 0 | N30: =IF(OR(A30="",B30=""),0,IF(OR($B$11="Sí",$B$11="Si"),B30*0.05*$B$5,0)) -> 0 | O30: =IF(OR(A30="",C30="",NOT(OR($B$8="Sí",$B$8="Si"))),0,IF(ISNUMBER(SEARCH("Source",E30)),C30*$AA$1,0)) -> 0
E31: =IF(A31="","",IFERROR(INDEX('Tarifas oficiales'!$B$4:$B$101,MATCH(A31,'Tarifas oficiales'!$C$4:$C$101,0)),"")) | F31: =K31+L31+M31+N31 -> 0 | G31: =F31+O31 -> 0 | H31: =IF(A31="","",IF(NOT(ISNUMBER(I31)),"⚠ Contact us: pon el $/tarea·h en Override (columna D)",IF(E31="Sink","Sink: sale del cluster. Ingress = 0.","Source: escribe a Confluent Cloud."))) | I31: =IF(A31="","",IF(D31<>"",D31,IFERROR(IF($B$6="Min",INDEX('Tarifas oficiales'!$D$4:$D$101,MATCH(A31,'Tarifas oficiales'!$C$4:$C$101,0)),IF($B$6="Max",INDEX('Tarifas oficiales'!$E$4:$E$101,MATCH(A31,'Tarifas oficiales'!$C$4:$C$101,0)),INDEX('Tarifas oficiales'!$F$4:$F$101,MATCH(A31,'Tarifas oficiales'!$C$4:$C$101,0)))),""))) | J31: =IF(A31="","",IFERROR(INDEX('Tarifas oficiales'!$G$4:$G$101,MATCH(A31,'Tarifas oficiales'!$C$4:$C$101,0)),0.025)) | K31: =IF(OR(A31="",B31="",NOT(ISNUMBER(I31))),0,B31*I31*$B$5) -> 0 | L31: =IF(OR(A31="",C31="",NOT(ISNUMBER(J31))),0,C31*J31) -> 0 | M31: =IF(OR(A31="",B31=""),0,IF(OR($B$10="Sí",$B$10="Si"),B31*0.03*$B$5,0)) -> 0 | N31: =IF(OR(A31="",B31=""),0,IF(OR($B$11="Sí",$B$11="Si"),B31*0.05*$B$5,0)) -> 0 | O31: =IF(OR(A31="",C31="",NOT(OR($B$8="Sí",$B$8="Si"))),0,IF(ISNUMBER(SEARCH("Source",E31)),C31*$AA$1,0)) -> 0
E32: =IF(A32="","",IFERROR(INDEX('Tarifas oficiales'!$B$4:$B$101,MATCH(A32,'Tarifas oficiales'!$C$4:$C$101,0)),"")) | F32: =K32+L32+M32+N32 -> 0 | G32: =F32+O32 -> 0 | H32: =IF(A32="","",IF(NOT(ISNUMBER(I32)),"⚠ Contact us: pon el $/tarea·h en Override (columna D)",IF(E32="Sink","Sink: sale del cluster. Ingress = 0.","Source: escribe a Confluent Cloud."))) | I32: =IF(A32="","",IF(D32<>"",D32,IFERROR(IF($B$6="Min",INDEX('Tarifas oficiales'!$D$4:$D$101,MATCH(A32,'Tarifas oficiales'!$C$4:$C$101,0)),IF($B$6="Max",INDEX('Tarifas oficiales'!$E$4:$E$101,MATCH(A32,'Tarifas oficiales'!$C$4:$C$101,0)),INDEX('Tarifas oficiales'!$F$4:$F$101,MATCH(A32,'Tarifas oficiales'!$C$4:$C$101,0)))),""))) | J32: =IF(A32="","",IFERROR(INDEX('Tarifas oficiales'!$G$4:$G$101,MATCH(A32,'Tarifas oficiales'!$C$4:$C$101,0)),0.025)) | K32: =IF(OR(A32="",B32="",NOT(ISNUMBER(I32))),0,B32*I32*$B$5) -> 0 | L32: =IF(OR(A32="",C32="",NOT(ISNUMBER(J32))),0,C32*J32) -> 0 | M32: =IF(OR(A32="",B32=""),0,IF(OR($B$10="Sí",$B$10="Si"),B32*0.03*$B$5,0)) -> 0 | N32: =IF(OR(A32="",B32=""),0,IF(OR($B$11="Sí",$B$11="Si"),B32*0.05*$B$5,0)) -> 0 | O32: =IF(OR(A32="",C32="",NOT(OR($B$8="Sí",$B$8="Si"))),0,IF(ISNUMBER(SEARCH("Source",E32)),C32*$AA$1,0)) -> 0
A33: SUMA | B33: =SUM(B21:B32) -> 5 | C33: =SUM(C21:C32) -> 35000 | F33: =SUM(F21:F32) -> 1369.6115 | G33: =SUM(G21:G32) -> 1579.6115 | K33: =SUM(K21:K32) -> 385.1115 | L33: =SUM(L21:L32) -> 875 | M33: =SUM(M21:M32) -> 109.5 | N33: =SUM(N21:N32) -> 0 | O33: =SUM(O21:O32) -> 210
A35: Fórmulas oficiales: coste_tareas = tareas × $/tarea/h × horas | coste_datos = GB × $/GB (pre-compresión) | ingress = GB × $/GB del cluster (solo Source). No incluye eCKU/CKU, storage, Schema Registry ni Flink. No es una cotización: los rangos $/tarea/h varían por región.

Sheet Guía de opciones
A1: Qué significa cada campo — guía para equipos de negocio
A2: Esta calculadora estima la factura mensual de un conector administrado que mueve datos hacia (o desde) Confluent Cloud. No es una cotización. En la hoja Calculadora, las celdas amarillas se eligen o se escriben; el resto se calcula solo.
A4: Opciones (bloque 1 de la Calculadora)
A5: Campo | B5: En palabras simples | C5: Qué implica en la factura | D5: Qué elegir | E5: Valor típico en el banco
A6: Horas / mes | B6: Cuántas horas del mes se considera el conector «encendido». Es el reloj de la factura, no un horario laboral. | C6: Todas las partidas que se cobran por hora (tareas, PrivateLink, SMT, Connect dedicado) se multiplican por este número. | D6: Déjalo en 730 si la integración opera todo el mes (24×7). No lo uses para «apagar» un conector: pausar puede seguir cobrando hasta eliminarlo. | E6: 730 (mes promedio: 24 × 365 / 12).
A7: Tarifa de tarea | B7: Precio de cada unidad de trabajo del conector durante una hora. Piensa en «cuántos operarios paralelos tiene la integración» (eso son las tareas) y «cuánto cuesta cada operario por hora» (eso es esta tarifa). | C7: Confluent publica un rango ($ mínimo – $ máximo) porque el precio cambia por región. La calculadora usa Min, el promedio o Max. Luego: tareas × tarifa × horas. | D7: Media para una estimación de presentación. Min si quieres el escenario más barato del rango público. Max si quieres ir conservador (presupuesto). Si hay precio de contrato, ignora esto y usa Override en la tabla. | E7: Media.
A8: Tipo de cluster Kafka | B8: El plan del cluster donde viven los topics (el «almacén» de eventos). No es el conector: es la plataforma a la que el conector escribe o de la que lee. | C8: Cambia el precio por GB de escritura al cluster (ingress). No cambia el precio por tarea del conector. Basic es el GB más caro; Dedicated, el más barato por GB (con mínimo oficial). | D8: Elige el plan real del entorno que estás costando (DESA / CERT / PROD). Pregunta a Plataforma si no lo tienes claro. | E8: Dedicated en producción.
A9: Incluir escritura a Kafka | B9: ¿Hay que sumar el peaje por meter datos en el cluster, además del precio del conector? Es un cargo distinto: el conector es el «camión»; el ingress es el «peaje de la autopista». | C9: Si está en Sí y el conector es Source, se suma GB × $/GB del cluster. Si es Sink (sacar datos hacia ADLS, Snowflake, etc.), este peaje de entrada no aplica. | D9: Sí cuando el caso es «un sistema del banco escribe a Confluent Cloud» (Event Hubs, IBM MQ, CDC, S3 Source…). No cuando el caso es «Confluent Cloud escribe a otro destino». | E9: Sí para conectores Source.
A10: Connect dedicado | B10: Una capacidad extra del servicio de conectores que Confluent factura cuando el cluster Kafka es Dedicated. No es un conector más: es el «local» donde corren los conectores en ese tipo de cluster. | C10: Cargo fijo por hora del entorno (0,27778 USD/h × horas). No se multiplica por el número de conectores de la tabla. Un Sí cubre todo el escenario. | D10: Sí si Plataforma confirma cluster Dedicated con Connect dedicado. No en Basic/Standard, o si aún no aplica. | E10: No, salvo confirmación de Plataforma.
A11: PrivateLink | B11: Conexión de red privada entre la red del banco y Confluent, sin salir a internet público. Es un requisito de seguridad/arquitectura, no una opción de «mejor rendimiento» para negocio. | C11: Recargo por cada tarea y hora (0,03 USD × tareas × horas). Si hay 3 tareas, se cobra 3 veces. | D11: Sí solo si el diseño de red del caso usa PrivateLink hacia los conectores. Si no lo sabes, deja No y valida con Arquitectura. | E11: No, salvo que Arquitectura lo exija.
A12: Custom SMT | B12: Transformaciones de datos dentro del conector (renombrar campos, enmascarar, cambiar formato). «Custom» significa hechas a medida, no las que vienen de serie. | C12: Recargo por cada tarea y hora (0,05 USD × tareas × horas). Las transformaciones estándar no tienen este cargo. | D12: No en el caso general. Sí solo si Desarrollo confirma que el conector usa un plugin SMT propio. | E12: No.
A14: Campos de la tabla de conectores (bloque 2)
A15: Campo | B15: En palabras simples | C15: Qué implica en la factura | D15: Qué elegir | E15: Valor típico en el banco
A16: Conector | B16: Qué integración se está costando. Source = trae datos a Confluent Cloud. Sink = saca datos de Confluent Cloud. | C16: Cada conector tiene su propio rango de tarifa por tarea y su precio por GB de Connect. | D16: Elige en la lista el nombre + tipo (ej. Azure Event Hubs [Source]). No mezcles Source y Sink del mismo producto sin mirar el tipo. | E16: El de tu caso de uso.
A17: Tareas (tasks.max) | B17: Cuántas unidades de trabajo en paralelo tiene el conector. Más tareas = más capacidad (y más coste por hora). | C17: Se multiplica por la tarifa de tarea y por las horas. También multiplica PrivateLink y SMT si están en Sí. | D17: Usa el valor de diseño (a menudo 1 a 3). No pongas un número «por si acaso»: cada tarea extra se paga todo el mes. | E17: El que defina el diseño técnico (ejemplo de la doc: 3).
A18: GB / mes | B18: Volumen de datos del mes, medido antes de comprimir. Es el tamaño «real» de lo que se mueve, no el tamaño ya compactado en disco. | C18: Connect cobra por GB movido. Si es Source y «Incluir escritura» está en Sí, el cluster cobra otro GB de entrada. | D18: Estima el volumen de negocio del mes (eventos × tamaño medio). Si no hay dato, pide a TI un promedio reciente. | E18: El volumen real o el de la lámina (ejemplo de la doc: 15 000 GB = 15 TB).
A19: Override $/tarea·h | B19: Precio por tarea y hora pactado o pedido a Confluent, cuando la lista pública dice «Contact us» o hay contrato. | C19: Si lo llenas, sustituye Min/Media/Max para esa fila. | D19: Déjalo vacío si usas el rango público. Rellénalo solo con un número de contrato o de «Contact us». | E19: Vacío.
A20: Tipo / Connect $/mes / TOTAL | B20: Celdas verdes: no se rellenan. Tipo lo saca la lista. Connect $/mes es el conector. TOTAL suma también el peaje de escritura a Kafka si aplica. | C20: El recuadro verde grande «TOTAL ESTIMADO / MES» es la cifra para la lámina (conectores + extras de Opciones). | D20: No editar. Si sale 0, falta conector, tareas, GB, o el conector es «Contact us» sin Override. | E20: Calculado.
A22: Qué NO incluye esta calculadora (para no inflar ni quedarse corta la lámina) • El cluster Kafka en sí (eCKU / CKU), almacenamiento de topics, Schema Registry ni Flink. • Egress (sacar datos de la nube), soporte Premier, ni impuestos. • El coste self-managed (AKS, personas, licencias on‑prem): eso está en el documento de comparación, no aquí. Los precios públicos cambian por región y contrato. Validar con Confluent antes de un presupuesto formal.

Sheet Tarifas oficiales
A1: Tarifas públicas — Fully managed Kafka connectors (Confluent Cloud)
A2: Fuente: https://www.confluent.io/confluent-cloud/connect-pricing/ | Billing: https://docs.confluent.io/cloud/current/billing/billing-dimensions.html | Throughput pre-compresión. 1 GB = 2^30 bytes (GiB). Precios en USD; varían por región. No es cotización.
A3: Conector | B3: Tipo | C3: Clave | D3: Task min ($/tarea·h) | E3: Task max ($/tarea·h) | F3: Task media ($/tarea·h) | G3: Data transfer ($/GB) | I3: Cargos adicionales (oficiales)
A4: Custom (BYO plugin) | B4: Source or Sink | C4: Custom (BYO plugin) [Source or Sink] | D4: 0.1 | E4: 0.2 | F4: 0.15 | G4: 0.025 | I4: Concepto | J4: USD | K4: Nota
A5: ActiveMQ | B5: Source | C5: ActiveMQ [Source] | D5: 0.05 | E5: 0.1 | F5: 0.075 | G5: 0.025 | I5: Horas/mes (doc flink-v1) | J5: 730 | K5: 24×365/12 ≈ 730
A6: Amazon CloudWatch Logs | B6: Source | C6: Amazon CloudWatch Logs [Source] | D6: 0.15 | E6: 0.3 | F6: 0.225 | G6: 0.025 | I6: Connect dedicado ($/h) | J6: 0.27778 | K6: CONNECT_CAPACITY — cluster Dedicated
A7: Amazon DynamoDB CDC | B7: Source | C7: Amazon DynamoDB CDC [Source] | D7: Contact us | E7: Contact us | F7: Contact us | G7: 0.025 | I7: PrivateLink ($/tarea·h) | J7: 0.03 | K7: endpoints PrivateLink
A8: Amazon Kinesis | B8: Source | C8: Amazon Kinesis [Source] | D8: 0.017 | E8: 0.0347 | F8: 0.02585 | G8: 0.025 | I8: Custom SMT ($/tarea·h) | J8: 0.05 | K8: SMT personalizados
A9: Amazon S3 | B9: Source | C9: Amazon S3 [Source] | D9: 0.05 | E9: 0.1 | F9: 0.075 | G9: 0.025 | I9: Connect data transfer default ($/GB) | J9: 0.025 | K9: pre-compresión
A10: Amazon SQS | B10: Source | C10: Amazon SQS [Source] | D10: 0.05 | E10: 0.1 | F10: 0.075 | G10: 0.025 | I10: Kafka ingress Basic ($/GB) | J10: 0.05 | K10: KAFKA_NETWORK_WRITE — conector source escribe al cluster
A11: Azure Blob Storage | B11: Source | C11: Azure Blob Storage [Source] | D11: 0.05 | E11: 0.1 | F11: 0.075 | G11: 0.025 | I11: Kafka ingress Standard min ($/GB) | J11: 0.035 | K11: rango oficial 0.035–0.050
A12: Azure Cosmos DB | B12: Source | C12: Azure Cosmos DB [Source] | D12: 0.15 | E12: 0.3 | F12: 0.225 | G12: 0.025 | I12: Kafka ingress Enterprise min ($/GB) | J12: 0.02 | K12: rango oficial 0.020–0.050
A13: Azure Cosmos DB V2 | B13: Source | C13: Azure Cosmos DB V2 [Source] | D13: 0.15 | E13: 0.3 | F13: 0.225 | G13: 0.025 | I13: Kafka ingress Dedicated min ($/GB) | J13: 0.014 | K13: rango oficial 0.014–0.030
A14: Azure Event Hubs | B14: Source | C14: Azure Event Hubs [Source] | D14: 0.017 | E14: 0.0347 | F14: 0.02585 | G14: 0.025
A15: Azure Service Bus | B15: Source | C15: Azure Service Bus [Source] | D15: 0.05 | E15: 0.1 | F15: 0.075 | G15: 0.025
A16: Couchbase Source | B16: Source | C16: Couchbase Source [Source] | D16: 0.3 | E16: 0.3 | F16: 0.3 | G16: 0.025
A17: Datagen | B17: Source | C17: Datagen [Source] | D17: 0.017 | E17: 0.0347 | F17: 0.02585 | G17: 0.025
A18: Debezium MariaDB CDC | B18: Source | C18: Debezium MariaDB CDC [Source] | D18: Contact us | E18: Contact us | F18: Contact us | G18: 0.025
A19: Github | B19: Source | C19: Github [Source] | D19: 0.15 | E19: 0.3 | F19: 0.225 | G19: 0.025
A20: Google Cloud Pub/Sub | B20: Source | C20: Google Cloud Pub/Sub [Source] | D20: 0.017 | E20: 0.0347 | F20: 0.02585 | G20: 0.025
A21: Google Cloud Storage | B21: Source | C21: Google Cloud Storage [Source] | D21: 0.05 | E21: 0.1 | F21: 0.075 | G21: 0.025
A22: HTTP | B22: Source | C22: HTTP [Source] | D22: 0.15 | E22: 0.3 | F22: 0.225 | G22: 0.025
A23: HTTP V2 | B23: Source | C23: HTTP V2 [Source] | D23: 0.15 | E23: 0.3 | F23: 0.225 | G23: 0.025
A24: IBM MQ | B24: Source | C24: IBM MQ [Source] | D24: 0.05 | E24: 0.1 | F24: 0.075 | G24: 0.025
A25: InfluxDB 2 | B25: Source | C25: InfluxDB 2 [Source] | D25: 0.15 | E25: 0.3 | F25: 0.225 | G25: 0.025
A26: Jira | B26: Source | C26: Jira [Source] | D26: 0.15 | E26: 0.3 | F26: 0.225 | G26: 0.025
A27: MariaDB CDC | B27: Source | C27: MariaDB CDC [Source] | D27: Contact us | E27: Contact us | F27: Contact us | G27: 0.025
A28: Microsoft SQL Server | B28: Source | C28: Microsoft SQL Server [Source] | D28: 0.017 | E28: 0.0347 | F28: 0.02585 | G28: 0.025
A29: Microsoft SQL Server CDC (Debezium) | B29: Source | C29: Microsoft SQL Server CDC (Debezium) [Source] | D29: 0.104 | E29: 0.2083 | F29: 0.15615 | G29: 0.025
A30: Microsoft SQL Server CDC V2 (Debezium) | B30: Source | C30: Microsoft SQL Server CDC V2 (Debezium) [Source] | D30: Contact us | E30: Contact us | F30: Contact us | G30: 0.025
A31: MongoDB Atlas | B31: Source | C31: MongoDB Atlas [Source] | D31: 0.15 | E31: 0.3 | F31: 0.225 | G31: 0.025
A32: MQTT | B32: Source | C32: MQTT [Source] | D32: 0.05 | E32: 0.1 | F32: 0.075 | G32: 0.025
A33: MySQL | B33: Source | C33: MySQL [Source] | D33: 0.017 | E33: 0.0347 | F33: 0.02585 | G33: 0.025
A34: MySQL CDC (Debezium) | B34: Source | C34: MySQL CDC (Debezium) [Source] | D34: 0.104 | E34: 0.2083 | F34: 0.15615 | G34: 0.025
A35: MySQL CDC V2 (Debezium) | B35: Source | C35: MySQL CDC V2 (Debezium) [Source] | D35: Contact us | E35: Contact us | F35: Contact us | G35: 0.025
A36: Oracle Database | B36: Source | C36: Oracle Database [Source] | D36: 0.017 | E36: 0.0347 | F36: 0.02585 | G36: 0.025
A37: PostgreSQL | B37: Source | C37: PostgreSQL [Source] | D37: 0.017 | E37: 0.0347 | F37: 0.02585 | G37: 0.025
A38: PostgreSQL CDC (Debezium) | B38: Source | C38: PostgreSQL CDC (Debezium) [Source] | D38: 0.104 | E38: 0.2083 | F38: 0.15615 | G38: 0.025
A39: PostgreSQL CDC V2 (Debezium) | B39: Source | C39: PostgreSQL CDC V2 (Debezium) [Source] | D39: Contact us | E39: Contact us | F39: Contact us | G39: 0.025
A40: RabbitMQ | B40: Source | C40: RabbitMQ [Source] | D40: 0.05 | E40: 0.1 | F40: 0.075 | G40: 0.025
...

Sheet Referencias
A1: Fuentes oficiales y del repo flink-v1
A3: Documento | B3: URL / ruta
A4: Managed Kafka Connector Pricing | B4: https://www.confluent.io/confluent-cloud/connect-pricing/
A5: Billing dimensions (Connect + Kafka ingress) | B5: https://docs.confluent.io/cloud/current/billing/billing-dimensions.html
A6: Billing overview | B6: https://docs.confluent.io/cloud/current/billing/overview.html
A7: Confluent Cloud pricing (cluster ingress) | B7: https://www.confluent.io/pricing/
A8: flink-v1 — comparación self vs full-managed | B8: flink-v1/docs/CONNECTORS_SELF_MANAGED_VS_FULL_MANAGED.md
A11: Cómo usarla 1. Lee la hoja «Guía de opciones» si eres de negocio o es la primera vez. 2. En Calculadora, celdas amarillas: cluster, tarifa Min/Media/Max y Sí/No de extras. 3. En la tabla, elige el conector (flecha), escribe tareas y GB/mes. 4. El TOTAL ESTIMADO / MES se actualiza solo. 5. Si el conector es «Contact us», rellena Override $/tarea·h. 6. No sustituye una cotización de Confluent.
